When I throw an exception
Then the test should pass